Workbook

Sheet Portfolio summary
A1: DANANTARA | Strategic-project portfolio
A2: 40 slots retained from the supplied graphic. Only 18 are named. Company assignments are recommendations unless a published platform remit is identified. Estimates are source figures, not approved budgets. As of 1 October 2026.
A5: Source cluster | B5: Project slots | C5: Named | D5: Unnamed | E5: Named budget (IDR bn) | F5: Graphic top-right cluster total (IDR bn) | G5: Unallocated within graphic (IDR bn) | H5: Lower-left alternative total (IDR bn)
A6: Minerals | B6: =COUNTIF('Projects 40'!B6:B45,A6) -> 5 | C6: =COUNTIFS('Projects 40'!B6:B45,A6,'Projects 40'!D6:D45,"Named in supplied graphic") -> 5 | D6: =B6-C6 -> 0 | E6: =SUMIF('Projects 40'!B6:B45,A6,'Projects 40'!L6:L45) -> 86874.118 | F6: 86874.118 | G6: =F6-E6 -> 0 | H6: 283850
A7: Infrastructure | B7: =COUNTIF('Projects 40'!B6:B45,A7) -> 14 | C7: =COUNTIFS('Projects 40'!B6:B45,A7,'Projects 40'!D6:D45,"Named in supplied graphic") -> 5 | D7: =B7-C7 -> 9 | E7: =SUMIF('Projects 40'!B6:B45,A7,'Projects 40'!L6:L45) -> 288968 | F7: 1217918.8 | G7: =F7-E7 -> 928950.84 | H7: 1274570
A8: Defense | B8: =COUNTIF('Projects 40'!B6:B45,A8) -> 3 | C8: =COUNTIFS('Projects 40'!B6:B45,A8,'Projects 40'!D6:D45,"Named in supplied graphic") -> 3 | D8: =B8-C8 -> 0 | E8: =SUMIF('Projects 40'!B6:B45,A8,'Projects 40'!L6:L45) -> 24360 | F8: 24360 | G8: =F8-E8 -> 0 | H8: 81100
A9: Others | B9: =COUNTIF('Projects 40'!B6:B45,A9) -> 18 | C9: =COUNTIFS('Projects 40'!B6:B45,A9,'Projects 40'!D6:D45,"Named in supplied graphic") -> 5 | D9: =B9-C9 -> 13 | E9: =SUMIF('Projects 40'!B6:B45,A9,'Projects 40'!L6:L45) -> 204768.23 | F9: 743381.44 | G9: =F9-E9 -> 538613.2 | H9: 451940
A10: Total | B10: =SUM(B6:B9) -> 40 | C10: =SUM(C6:C9) -> 18 | D10: =SUM(D6:D9) -> 22 | E10: =SUM(E6:E9) -> 604970.35 | F10: =SUM(F6:F9) -> 2072534.4 | G10: =SUM(G6:G9) -> 1467564 | H10: =SUM(H6:H9) -> 2091460
A12: Budget reconciliation | B12: IDR billion | C12: Interpretation | D12: Source
A13: Graphic headline | B13: 2091460 | C13: Headline equals lower-left allocation total | D13: User supplied: 40 Strategic Projects.jpeg; date / estimate basis not stated
A14: Headline less top-right total | B14: =B13-F10 -> 18925.611 | C14: Unreconciled source difference; do not allocate to unnamed projects | D14: User supplied: 40 Strategic Projects.jpeg; date / estimate basis not stated
A15: Headline less named projects | B15: =B13-E10 -> 1486489.6 | C15: Unallocated / unverified scope; not an estimate for 22 missing projects | D15: User supplied: 40 Strategic Projects.jpeg; date / estimate basis not stated
A17: Planning assumption | B17: Editable input | C17: Interpretation | D17: Basis
A18: Illustrative allowance on known source amounts | B18: 0.15 | C18: Used in Projects 40 column M only; not approved contingency, inflation, P90 or an AACE accuracy range | D18: Analyst scenario assumption; replace with quantified project risk
A19: Known project planning amount (IDR billion) | B19: =SUM('Projects 40'!M6:M45) -> 695715.91 | C19: Excludes 22 unnamed slots; not a full portfolio budget | D19: Calculated from source base + allowance
A22: Ownership | B22: Use Companies tier filter. The 52 companies are the statutory transfer roster, not all directly owned by BPI. Several are operating subsidiaries with direct transferred share exposure. Obtain updated DAM registry and subsequent transfer instruments.
A23: Project ownership | B23: Named operator capability does not prove project appointment. Denera is a published DIM waste platform, but exact three infographic waste-project assignments remain unverified.
A24: Budget scope | B24: Graphic top-right and lower-left allocations conflict. Named budgets are transcribed in IDR million and converted by /1,000 to IDR billion. Date, cost boundary, capacity and estimate maturity are not provided.
A25: PLTS 100 GW | B25: Source budget implies IDR 2.314 million per kW if entire 100 GW scope is covered. Verify units, capacity basis, grid / storage exclusions and whether amount covers a phase before using for FID.
A26: Unresolved labels | B26: Atoma (LTi), CDME and CPE are retained verbatim. Conditional industry interpretations must be confirmed from official project briefs. No partner is selected for Atoma or the multi-metal umbrella.
A27: Execution governance | B27: Strategic office defines cluster roadmap / resolves cross-SOE interfaces; DAM oversees operating performance and asset stewardship; DIM leads investment structuring and co-investment. Company boards retain project accountability and FID authorities.
A28: Next data request | B28: Obtain official 40-project register, project charters, appointed sponsors, capacity / location, current gate, approved cost baseline and cash flow, permits, committed financing, partner contracts and schedules.
A29: Sources / refresh | B29: User graphic and Strategi D.docx guide scope. PP15/2025 establishes transfer baseline; official Danantara and partner pages support platform/capability mapping. Analyst fields should be validated by Danantara before investment decisions.

Sheet Projects 40
A1: DANANTARA | 40 strategic-project register
A2: Source-led register as of 1 October 2026. SP IDs are workbook IDs. 18 named projects; 22 unnamed slots. Responsibilities, horizons, technologies and milestones are recommendations unless explicitly stated.
A5: Workbook ID | B5: Source cluster | C5: Project name | D5: Identification status | E5: Business cluster | F5: Proposed accountable group | G5: Existing operator / candidate | H5: Assignment evidence | I5: Current milestone | J5: Proposed horizon | K5: Graphic budget (IDR million) | L5: Converted estimate (IDR billion) | M5: Planning amount incl. allowance (IDR billion) | N5: Technology required / scope condition | O5: Potential global partner | P5: Principal execution / financing risk | Q5: Project-specific milestone sequence | R5: Budget / identity source | S5: Mapping evidence / source
A6: SP-01 | B6: Minerals | C6: Silica | D6: Named in supplied graphic | E6: Industrial minerals | F6: MIND ID | G6: MIND ID-led SPV; operator to be selected | H6: Analyst-proposed responsibility; appointment unverified | I6: Current gate unverified | K6: 8900000 | L6: =IF(K6="","",K6/1000) -> 8900 | M6: =IF(L6="","",L6*(1+'Portfolio summary'!B18)) -> 10235 | N6: Beneficiation; impurity removal; product qualification. Silicon/polysilicon is a separate scope decision. | O6: Sibelco | P6: Ore variability; unclear silica versus silicon scope | Q6: Resource sampling → pilot purification → customer grade approval | R6: User supplied: 40 Strategic Projects.jpeg; date / estimate basis not stated | S6: https://www.danantaraindonesia.co.id/dam/portfolio
A7: SP-02 | B7: Minerals | C7: Copper | D7: Named in supplied graphic | E7: Copper / metal fabrication | F7: MIND ID | G7: PT Freeport Indonesia; downstream SPV candidate | H7: Analyst-proposed responsibility; appointment unverified | I7: Current gate unverified | K7: 2000000 | L7: =IF(K7="","",K7/1000) -> 2000 | M7: =IF(L7="","",L7*(1+'Portfolio summary'!B18)) -> 2300 | N7: Smelting/refining or downstream copper rod/foil; scope must be fixed before FEED. | O7: Aurubis | P7: Scope and capacity absent; concentrate balance; product demand | Q7: Capacity / feedstock definition → process selection → product qualification | R7: User supplied: 40 Strategic Projects.jpeg; date / estimate basis not stated | S7: https://www.danantaraindonesia.co.id/dam/portfolio
A8: SP-03 | B8: Minerals | C8: Project Atoma (LTi) | D8: Named in supplied graphic | E8: Unresolved mineral scope | F8: MIND ID — conditional | G8: No confirmed operator; minerals SPV candidate | H8: Analyst-proposed responsibility; appointment unverified | I8: Current gate unverified | K8: 380000 | L8: =IF(K8="","",K8/1000) -> 380 | M8: =IF(L8="","",L8*(1+'Portfolio summary'!B18)) -> 437 | N8: LTi is unexpanded in source. IF lithium: resource assessment, extraction pilot and lithium purification. | O8: Not shortlisted pending scope | P8: Acronym, resource and economics unconfirmed | Q8: Confirm official project brief → resource test → route-selection pilot | R8: User supplied: 40 Strategic Projects.jpeg; date / estimate basis not stated | S8: https://www.danantaraindonesia.co.id/dam/portfolio
A9: SP-04 | B9: Minerals | C9: Project Tarsius Phase 1 (LTJ) | D9: Named in supplied graphic | E9: Rare earths — proposed interpretation | F9: MIND ID | G9: PT Timah candidate; MIND ID-led SPV | H9: Analyst-proposed responsibility; appointment unverified | I9: Current gate unverified | K9: 2300000 | L9: =IF(K9="","",K9/1000) -> 2300 | M9: =IF(L9="","",L9*(1+'Portfolio summary'!B18)) -> 2645 | N9: Beneficiation, cracking/leaching, separation and purification; radiological residue management if required. | O9: Lynas Rare Earths | P9: Recovery economics; residue management; customer qualification | Q9: Mineralogy / residue characterization → separation pilot → qualified oxide | R9: User supplied: 40 Strategic Projects.jpeg; date / estimate basis not stated | S9: https://www.danantaraindonesia.co.id/dam/portfolio
A10: SP-05 | B10: Minerals | C10: Al, Fe, Ni, Mn (Auto, Aerospace, Defense) | D10: Named in supplied graphic | E10: Advanced metals / alloys | F10: MIND ID + Krakatau Steel | G10: Inalum / Antam / Krakatau Steel; multiple SPVs | H10: Analyst-proposed responsibility; appointment unverified | I10: Current gate unverified | K10: 73294118 | L10: =IF(K10="","",K10/1000) -> 73294.118 | M10: =IF(L10="","",L10*(1+'Portfolio summary'!B18)) -> 84288.236 | N10: Aluminium refining/smelting; specialty steel/alloys; nickel/manganese processing; testing and certification. | O10: Rio Tinto (aluminium); POSCO (steel) — package-specific | P10: Umbrella allocation unknown; power intensity; certification | Q10: Separate investment packages → feedstock / power contracts → customer certification | R10: User supplied: 40 Strategic Projects.jpeg; date / estimate basis not stated | S10: https://www.danantaraindonesia.co.id/dam/portfolio
A11: SP-06 | B11: Infrastructure | C11: PLTS 100 GW | D11: Named in supplied graphic | E11: Renewable power | F11: PLN | G11: PLN Nusantara Power; PLN-led project SPVs | H11: Analyst-proposed responsibility; appointment unverified | I11: Current gate unverified | K11: 231400000 | L11: =IF(K11="","",K11/1000) -> 231400 | M11: =IF(L11="","",L11*(1+'Portfolio summary'!B18)) -> 266110 | N11: PV, inverters, grid interconnection; storage and network upgrades where needed. | O11: Masdar | P11: Grid hosting capacity; tariff; local content; budget scope | Q11: Tranche grid studies → PPA / land → FID → energization → performance acceptance | R11: User supplied: 40 Strategic Projects.jpeg; date / estimate basis not stated | S11: https://www.danantaraindonesia.co.id/dam/portfolio
A12: SP-07 | B12: Infrastructure | C12: Refinery | D12: Named in supplied graphic | E12: Oil refining | F12: Pertamina | G12: PT Kilang Pertamina Internasional | H12: Analyst-proposed responsibility; appointment unverified | I12: Current gate unverified | K12: 40940000 | L12: =IF(K12="","",K12/1000) -> 40940 | M12: =IF(L12="","",L12*(1+'Portfolio summary'!B18)) -> 47081 | N12: Process units, upgrading, hydrogen, utilities, process safety and digital control; configuration TBD. | O12: Aramco — configuration / commercial fit to be tested | P12: Crude slate; margin exposure; scope / location absent | Q12: Configuration / crude study → FEED / HAZOP → financial close → performance test | R12: User supplied: 40 Strategic Projects.jpeg; date / estimate basis not stated | S12: https://www.danantaraindonesia.co.id/dam/portfolio
A13: SP-08 | B13: Infrastructure | C13: Decentralized Waste Management | D13: Named in supplied graphic | E13: Circular economy / waste | F13: DIM / Denera | G13: PT Daya Energi Bersih Nusantara (Denera) | H13: Published platform remit; exact project assignment unverified | I13: Current gate unverified | K13: 4628000 | L13: =IF(K13="","",K13/1000) -> 4628 | M13: =IF(L13="","",L13*(1+'Portfolio summary'!B18)) -> 5322.2 | N13: Segregation, materials recovery, composting/AD or thermal conversion selected after waste characterization. | O13: Veolia | P13: Municipal payment; feedstock quality; collection coverage | Q13: Waste audit → service / feedstock contract → pilot → service-level acceptance | R13: User supplied: 40 Strategic Projects.jpeg; date / estimate basis not stated | S13: https://www.danantaraindonesia.co.id/media-center/press-releases/dim-cloa-batch-ii-wte-partners
A14: SP-09 | B14: Infrastructure | C14: Legacy Waste Processing – Landfill Mining | D14: Named in supplied graphic | E14: Circular economy / remediation | F14: DIM / Denera | G14: Denera-led SPV; local-government site owner | H14: Published platform remit; exact project assignment unverified | I14: Current gate unverified | K14: 6000000 | L14: =IF(K14="","",K14/1000) -> 6000 | M14: =IF(L14="","",L14*(1+'Portfolio summary'!B18)) -> 6900 | N14: Waste excavation, screening, material recovery; leachate, gas and residue management. | O14: Veolia — conditional remediation scope | P14: Geotechnical / contamination uncertainty; recovered material market | Q14: Site risk survey → trial excavation → approved remediation plan → recovery acceptance | R14: User supplied: 40 Strategic Projects.jpeg; date / estimate basis not stated | S14: https://www.danantaraindonesia.co.id/media-center/press-releases/dim-cloa-batch-ii-wte-partners
A15: SP-10 | B15: Infrastructure | C15: Legacy Waste Processing – RDF | D15: Named in supplied graphic | E15: Circular economy / alternative fuel | F15: DIM / Denera | G15: Denera-led SPV; Semen Indonesia as potential offtaker | H15: Published platform remit; exact project assignment unverified | I15: Current gate unverified | K15: 6000000 | L15: =IF(K15="","",K15/1000) -> 6000 | M15: =IF(L15="","",L15*(1+'Portfolio summary'!B18)) -> 6900 | N15: Sorting, drying, shredding, blending; fuel quality and cement-kiln acceptance. | O15: Veolia | P15: Calorific / chlorine variability; logistics; offtake | Q15: Waste characterization → RDF trial → kiln acceptance → offtake → commercial ramp | R15: User supplied: 40 Strategic Projects.jpeg; date / estimate basis not stated | S15: https://www.danantaraindonesia.co.id/media-center/press-releases/dim-cloa-batch-ii-wte-partners
A16: SP-11 | B16: Infrastructure | C16: Unspecified Infrastructure project 6 | D16: Unnamed slot in supplied graphic | E16: Unresolved | F16: Unassigned | G16: Unassigned | H16: No project scope available | I16: Unknown | J16: Not estimable | L16: =IF(K16="","",K16/1000) | M16: =IF(L16="","",L16*(1+'Portfolio summary'!B18)) | N16: Scope required | O16: Not shortlisted | P16: Name / sponsor / capacity / location / budget absent | Q16: Obtain official project brief | R16: User supplied: 40 Strategic Projects.jpeg; date / estimate basis not stated
A17: SP-12 | B17: Infrastructure | C17: Unspecified Infrastructure project 7 | D17: Unnamed slot in supplied graphic | E17: Unresolved | F17: Unassigned | G17: Unassigned | H17: No project scope available | I17: Unknown | J17: Not estimable | L17: =IF(K17="","",K17/1000) | M17: =IF(L17="","",L17*(1+'Portfolio summary'!B18)) | N17: Scope required | O17: Not shortlisted | P17: Name / sponsor / capacity / location / budget absent | Q17: Obtain official project brief | R17: User supplied: 40 Strategic Projects.jpeg; date / estimate basis not stated
A18: SP-13 | B18: Infrastructure | C18: Unspecified Infrastructure project 8 | D18: Unnamed slot in supplied graphic | E18: Unresolved | F18: Unassigned | G18: Unassigned | H18: No project scope available | I18: Unknown | J18: Not estimable | L18: =IF(K18="","",K18/1000) | M18: =IF(L18="","",L18*(1+'Portfolio summary'!B18)) | N18: Scope required | O18: Not shortlisted | P18: Name / sponsor / capacity / location / budget absent | Q18: Obtain official project brief | R18: User supplied: 40 Strategic Projects.jpeg; date / estimate basis not stated
A19: SP-14 | B19: Infrastructure | C19: Unspecified Infrastructure project 9 | D19: Unnamed slot in supplied graphic | E19: Unresolved | F19: Unassigned | G19: Unassigned | H19: No project scope available | I19: Unknown | J19: Not estimable | L19: =IF(K19="","",K19/1000) | M19: =IF(L19="","",L19*(1+'Portfolio summary'!B18)) | N19: Scope required | O19: Not shortlisted | P19: Name / sponsor / capacity / location / budget absent | Q19: Obtain official project brief | R19: User supplied: 40 Strategic Projects.jpeg; date / estimate basis not stated
A20: SP-15 | B20: Infrastructure | C20: Unspecified Infrastructure project 10 | D20: Unnamed slot in supplied graphic | E20: Unresolved | F20: Unassigned | G20: Unassigned | H20: No project scope available | I20: Unknown | J20: Not estimable | L20: =IF(K20="","",K20/1000) | M20: =IF(L20="","",L20*(1+'Portfolio summary'!B18)) | N20: Scope required | O20: Not shortlisted | P20: Name / sponsor / capacity / location / budget absent | Q20: Obtain official project brief | R20: User supplied: 40 Strategic Projects.jpeg; date / estimate basis not stated
A21: SP-16 | B21: Infrastructure | C21: Unspecified Infrastructure project 11 | D21: Unnamed slot in supplied graphic | E21: Unresolved | F21: Unassigned | G21: Unassigned | H21: No project scope available | I21: Unknown | J21: Not estimable | L21: =IF(K21="","",K21/1000) | M21: =IF(L21="","",L21*(1+'Portfolio summary'!B18)) | N21: Scope required | O21: Not shortlisted | P21: Name / sponsor / capacity / location / budget absent | Q21: Obtain official project brief | R21: User supplied: 40 Strategic Projects.jpeg; date / estimate basis not stated
A22: SP-17 | B22: Infrastructure | C22: Unspecified Infrastructure project 12 | D22: Unnamed slot in supplied graphic | E22: Unresolved | F22: Unassigned | G22: Unassigned | H22: No project scope available | I22: Unknown | J22: Not estimable | L22: =IF(K22="","",K22/1000) | M22: =IF(L22="","",L22*(1+'Portfolio summary'!B18)) | N22: Scope required | O22: Not shortlisted | P22: Name / sponsor / capacity / location / budget absent | Q22: Obtain official project brief | R22: User supplied: 40 Strategic Projects.jpeg; date / estimate basis not stated
A23: SP-18 | B23: Infrastructure | C23: Unspecified Infrastructure project 13 | D23: Unnamed slot in supplied graphic | E23: Unresolved | F23: Unassigned | G23: Unassigned | H23: No project scope available | I23: Unknown | J23: Not estimable | L23: =IF(K23="","",K23/1000) | M23: =IF(L23="","",L23*(1+'Portfolio summary'!B18)) | N23: Scope required | O23: Not shortlisted | P23: Name / sponsor / capacity / location / budget absent | Q23: Obtain official project brief | R23: User supplied: 40 Strategic Projects.jpeg; date / estimate basis not stated
A24: SP-19 | B24: Infrastructure | C24: Unspecified Infrastructure project 14 | D24: Unnamed slot in supplied graphic | E24: Unresolved | F24: Unassigned | G24: Unassigned | H24: No project scope available | I24: Unknown | J24: Not estimable | L24: =IF(K24="","",K24/1000) | M24: =IF(L24="","",L24*(1+'Portfolio summary'!B18)) | N24: Scope required | O24: Not shortlisted | P24: Name / sponsor / capacity / location / budget absent | Q24: Obtain official project brief | R24: User supplied: 40 Strategic Projects.jpeg; date / estimate basis not stated
A25: SP-20 | B25: Defense | C25: Alutsista | D25: Named in supplied graphic | E25: Defense manufacturing | F25: Len Industri / DEFEND ID | G25: Pindad / PT Dirgantara Indonesia / Dahana / PAL by work package | H25: Analyst-proposed responsibility; appointment unverified | I25: Current gate unverified | K25: 16124706 | L25: =IF(K25="","",K25/1000) -> 16124.706 | M25: =IF(L25="","",L25*(1+'Portfolio summary'!B18)) -> 18543.412 | N25: Systems engineering, precision manufacturing, quality assurance, testing, sustainment capability. | O25: Thales | P25: Procurement visibility; sovereign IP; export controls; sustainment | Q25: User requirements → design reviews → first article → acceptance → production readiness | R25: User supplied: 40 Strategic Projects.jpeg; date / estimate basis not stated | S25: https://www.danantaraindonesia.co.id/dam/portfolio
A26: SP-21 | B26: Defense | C26: Industri Galangan dan Komponen Kapal | D26: Named in supplied graphic | E26: Shipbuilding / marine supply chain | F26: Len Industri / DEFEND ID | G26: PT PAL; DKB / DPS / IKI for commercial packages | H26: Analyst-proposed responsibility; appointment unverified | I26: Current gate unverified | K26: 5235294 | L26: =IF(K26="","",K26/1000) -> 5235.294 | M26: =IF(L26="","",L26*(1+'Portfolio summary'!B18)) -> 6020.5881 | N26: Ship design, modular construction, welding qualification, propulsion integration, class certification. | O26: Naval Group | P26: Orderbook; transfer of skills/IP; supplier quality; yard capacity | Q26: Design / class approval → supplier qualification → construction → sea trials → delivery | R26: User supplied: 40 Strategic Projects.jpeg; date / estimate basis not stated | S26: https://www.danantaraindonesia.co.id/dam/portfolio
A27: SP-22 | B27: Defense | C27: Drone | D27: Named in supplied graphic | E27: Aerospace manufacturing | F27: Len Industri / DEFEND ID | G27: PT Dirgantara Indonesia; Len systems integration candidate | H27: Analyst-proposed responsibility; appointment unverified | I27: Current gate unverified | K27: 3000000 | L27: =IF(K27="","",K27/1000) -> 3000 | M27: =IF(L27="","",L27*(1+'Portfolio summary'!B18)) -> 3450 | N27: Airframe manufacturing, flight-control integration, assurance, airworthiness and production quality. | O27: Turkish Aerospace | P27: Design ownership; airworthiness; export approvals; customer specification | Q27: Requirements → preliminary / critical design review → prototype → certification → production readiness | R27: User supplied: 40 Strategic Projects.jpeg; date / estimate basis not stated | S27: https://www.danantaraindonesia.co.id/dam/portfolio
A28: SP-23 | B28: Others | C28: CDME | D28: Named in supplied graphic | E28: Coal chemicals — interpretation unconfirmed | F28: MIND ID — conditional | G28: PT Bukit Asam; Pertamina distribution / offtake candidate | H28: Analyst-proposed responsibility; appointment unverified | I28: Current gate unverified | K28: 46280000 | L28: =IF(K28="","",K28/1000) -> 46280 | M28: =IF(L28="","",L28*(1+'Portfolio summary'!B18)) -> 53222 | N28: IF coal-to-DME: gasification, syngas treatment, methanol/DME conversion, emissions and water management. | O28: CHN Energy — conditional route | P28: Acronym unconfirmed; subsidy / oil-price economics; carbon and water | Q28: Official scope → feedstock tests → product / subsidy case → pilot evidence → FEED | R28: User supplied: 40 Strategic Projects.jpeg; date / estimate basis not stated | S28: https://www.danantaraindonesia.co.id/dam/portfolio
A29: SP-24 | B29: Others | C29: CPE | D29: Named in supplied graphic | E29: Petrochemicals — unresolved acronym | F29: MIND ID / Pertamina — conditional | G29: PT Bukit Asam / KPI; lead depends on scope | H29: Analyst-proposed responsibility; appointment unverified | I29: Current gate unverified | K29: 71200000 | L29: =IF(K29="","",K29/1000) -> 71200 | M29: =IF(L29="","",L29*(1+'Portfolio summary'!B18)) -> 81880 | N29: CPE unexpanded. IF coal-to-petrochemicals/ethylene: gasification, methanol-to-olefins, separation/polymer chain. | O29: CHN Energy — conditional route | P29: Acronym / capacity unconfirmed; cost competitiveness; emissions | Q29: Confirm product scope → route comparison → market / water case → FEED → customer qualification | R29: User supplied: 40 Strategic Projects.jpeg; date / estimate basis not stated | S29: https://www.danantaraindonesia.co.id/dam/portfolio
A30: SP-25 | B30: Others | C30: Biodiesel | D30: Named in supplied graphic | E30: Biofuels / plantation value chain | F30: PTPN III / Agrinas Palma + Pertamina | G30: PTPN IV / Agrinas Palma feedstock; Pertamina fuel offtake; plant SPV TBD | H30: Analyst-proposed responsibility; appointment unverified | I30: Current gate unverified | K30: 75388235 | L30: =IF(K30="","",K30/1000) -> 75388.235 | M30: =IF(L30="","",L30*(1+'Portfolio summary'!B18)) -> 86696.47 | N30: FAME transesterification, pretreatment, glycerol handling, fuel-quality lab; HVO is a separate route. | O30: Wilmar | P30: Feedstock sustainability; palm / diesel spread; subsidy; FAME versus HVO scope | Q30: Feedstock / traceability → route decision → FEED → product standard → offtake / ramp | R30: User supplied: 40 Strategic Projects.jpeg; date / estimate basis not stated | S30: https://www.danantaraindonesia.co.id/dam/portfolio
A31: SP-26 | B31: Others | C31: EV Power Pack (Maritim Industry) | D31: Named in supplied graphic | E31: Marine batteries / electrification | F31: Len Industri / PAL + Pertamina — proposed | G31: PT PAL system integrator; cell supplier / pack SPV TBD | H31: Analyst-proposed responsibility; appointment unverified | I31: Current gate unverified | K31: 3000000 | L31: =IF(K31="","",K31/1000) -> 3000 | M31: =IF(L31="","",L31*(1+'Portfolio summary'!B18)) -> 3450 | N31: Cell sourcing, pack assembly, BMS, thermal / fire safety, marine type approval and vessel integration. | O31: Corvus Energy | P31: Safety / class approval; cell dependence; warranty; vessel demand | Q31: Vessel duty cycle → pack design → safety / type approval → vessel trials → serial readiness | R31: User supplied: 40 Strategic Projects.jpeg; date / estimate basis not stated | S31: https://www.danantaraindonesia.co.id/dam/portfolio
A32: SP-27 | B32: Others | C32: Biosimilar & Pharma Manufacturing | D32: Named in supplied graphic | E32: Biopharmaceuticals | F32: Bio Farma | G32: PT Bio Farma; manufacturing SPV if required | H32: Analyst-proposed responsibility; appointment unverified | I32: Current gate unverified | K32: 8900000 | L32: =IF(K32="","",K32/1000) -> 8900 | M32: =IF(L32="","",L32*(1+'Portfolio summary'!B18)) -> 10235 | N32: Cell culture, bioreactors, purification, aseptic fill/finish, GMP labs and comparability validation. | O32: Samsung Biologics | P32: IP / freedom to operate; clinical comparability; BPOM approval; quality | Q32: Molecule / IP choice → tech transfer → validated batches → regulatory approval → launch | R32: User supplied: 40 Strategic Projects.jpeg; date / estimate basis not stated | S32: https://www.danantaraindonesia.co.id/dam/portfolio
A33: SP-28 | B33: Others | C33: Unspecified Others project 6 | D33: Unnamed slot in supplied graphic | E33: Unresolved | F33: Unassigned | G33: Unassigned | H33: No project scope available | I33: Unknown | J33: Not estimable | L33: =IF(K33="","",K33/1000) | M33: =IF(L33="","",L33*(1+'Portfolio summary'!B18)) | N33: Scope required | O33: Not shortlisted | P33: Name / sponsor / capacity / location / budget absent | Q33: Obtain official project brief | R33: User supplied: 40 Strategic Projects.jpeg; date / estimate basis not stated
A34: SP-29 | B34: Others | C34: Unspecified Others project 7 | D34: Unnamed slot in supplied graphic | E34: Unresolved | F34: Unassigned | G34: Unassigned | H34: No project scope available | I34: Unknown | J34: Not estimable | L34: =IF(K34="","",K34/1000) | M34: =IF(L34="","",L34*(1+'Portfolio summary'!B18)) | N34: Scope required | O34: Not shortlisted | P34: Name / sponsor / capacity / location / budget absent | Q34: Obtain official project brief | R34: User supplied: 40 Strategic Projects.jpeg; date / estimate basis not stated
A35: SP-30 | B35: Others | C35: Unspecified Others project 8 | D35: Unnamed slot in supplied graphic | E35: Unresolved | F35: Unassigned | G35: Unassigned | H35: No project scope available | I35: Unknown | J35: Not estimable | L35: =IF(K35="","",K35/1000) | M35: =IF(L35="","",L35*(1+'Portfolio summary'!B18)) | N35: Scope required | O35: Not shortlisted | P35: Name / sponsor / capacity / location / budget absent | Q35: Obtain official project brief | R35: User supplied: 40 Strategic Projects.jpeg; date / estimate basis not stated
A36: SP-31 | B36: Others | C36: Unspecified Others project 9 | D36: Unnamed slot in supplied graphic | E36: Unresolved | F36: Unassigned | G36: Unassigned | H36: No project scope available | I36: Unknown | J36: Not estimable | L36: =IF(K36="","",K36/1000) | M36: =IF(L36="","",L36*(1+'Portfolio summary'!B18)) | N36: Scope required | O36: Not shortlisted | P36: Name / sponsor / capacity / location / budget absent | Q36: Obtain official project brief | R36: User supplied: 40 Strategic Projects.jpeg; date / estimate basis not stated
A37: SP-32 | B37: Others | C37: Unspecified Others project 10 | D37: Unnamed slot in supplied graphic | E37: Unresolved | F37: Unassigned | G37: Unassigned | H37: No project scope available | I37: Unknown | J37: Not estimable | L37: =IF(K37="","",K37/1000) | M37: =IF(L37="","",L37*(1+'Portfolio summary'!B18)) | N37: Scope required | O37: Not shortlisted | P37: Name / sponsor / capacity / location / budget absent | Q37: Obtain official project brief | R37: User supplied: 40 Strategic Projects.jpeg; date / estimate basis not stated
A38: SP-33 | B38: Others | C38: Unspecified Others project 11 | D38: Unnamed slot in supplied graphic | E38: Unresolved | F38: Unassigned | G38: Unassigned | H38: No project scope available | I38: Unknown | J38: Not estimable | L38: =IF(K38="","",K38/1000) | M38: =IF(L38="","",L38*(1+'Portfolio summary'!B18)) | N38: Scope required | O38: Not shortlisted | P38: Name / sponsor / capacity / location / budget absent | Q38: Obtain official project brief | R38: User supplied: 40 Strategic Projects.jpeg; date / estimate basis not stated
A39: SP-34 | B39: Others | C39: Unspecified Others project 12 | D39: Unnamed slot in supplied graphic | E39: Unresolved | F39: Unassigned | G39: Unassigned | H39: No project scope available | I39: Unknown | J39: Not estimable | L39: =IF(K39="","",K39/1000) | M39: =IF(L39="","",L39*(1+'Portfolio summary'!B18)) | N39: Scope required | O39: Not shortlisted | P39: Name / sponsor / capacity / location / budget absent | Q39: Obtain official project brief | R39: User supplied: 40 Strategic Projects.jpeg; date / estimate basis not stated
A40: SP-35 | B40: Others | C40: Unspecified Others project 13 | D40: Unnamed slot in supplied graphic | E40: Unresolved | F40: Unassigned | G40: Unassigned | H40: No project scope available | I40: Unknown | J40: Not estimable | L40: =IF(K40="","",K40/1000) | M40: =IF(L40="","",L40*(1+'Portfolio summary'!B18)) | N40: Scope required | O40: Not shortlisted | P40: Name / sponsor / capacity / location / budget absent | Q40: Obtain official project brief | R40: User supplied: 40 Strategic Projects.jpeg; date / estimate basis not stated
A41: SP-36 | B41: Others | C41: Unspecified Others project 14 | D41: Unnamed slot in supplied graphic | E41: Unresolved | F41: Unassigned | G41: Unassigned | H41: No project scope available | I41: Unknown | J41: Not estimable | L41: =IF(K41="","",K41/1000) | M41: =IF(L41="","",L41*(1+'Portfolio summary'!B18)) | N41: Scope required | O41: Not shortlisted | P41: Name / sponsor / capacity / location / budget absent | Q41: Obtain official project brief | R41: User supplied: 40 Strategic Projects.jpeg; date / estimate basis not stated
A42: SP-37 | B42: Others | C42: Unspecified Others project 15 | D42: Unnamed slot in supplied graphic | E42: Unresolved | F42: Unassigned | G42: Unassigned | H42: No project scope available | I42: Unknown | J42: Not estimable | L42: =IF(K42="","",K42/1000) | M42: =IF(L42="","",L42*(1+'Portfolio summary'!B18)) | N42: Scope required | O42: Not shortlisted | P42: Name / sponsor / capacity / location / budget absent | Q42: Obtain official project brief | R42: User supplied: 40 Strategic Projects.jpeg; date / estimate basis not stated
...

Sheet Companies
A1: DANANTARA | Company roster and business clusters
A2: Hierarchy is explicit: BPI organizational arms ≠ DAM portfolio holdings ≠ operating subsidiaries. 52-entry PP15/2025 baseline is not a certified current cap table. Cluster classification is analytical, aligned with published DAM sectors.
A5: Company / arm | B5: Ownership / organizational tier | C5: Holding / parent basis | D5: Industry / business cluster | E5: Primary business / strategic role | F5: Ownership / evidence qualification | G5: Source
A6: PT Danantara Asset Management (DAM) | B6: BPI organizational arm | C6: BPI Danantara | D6: Asset-management holding | E6: Portfolio operations / asset management | F6: Direct organizational tier; legal register / percentages not verified | G6: https://www.danantaraindonesia.co.id/dam/portfolio
A7: PT Danantara Investment Management (DIM) | B7: BPI organizational arm | C7: BPI Danantara | D7: Investment management | E7: Investment structuring / co-investment | F7: Direct organizational tier; legal register / percentages not verified | G7: https://www.danantaraindonesia.co.id/dim
A8: Danantara Development Management Fund (DDMF) | B8: BPI organizational arm | C8: BPI Danantara | D8: Development management | E8: Development platform | F8: Official ecosystem arm; legal entity / ownership confirmation required | G8: https://www.danantaraindonesia.co.id/
A9: Pertamina | B9: PP15/2025 transfer roster | C9: BKI → DAM (statutory baseline) | D9: Energy OilGas | E9: Integrated oil, gas and energy | F9: Series B / C transfer baseline, not proof of sole ownership or October 2026 immediate parent; verify registry | G9: https://peraturan.bpk.go.id/Details/316689/pp-no-15-tahun-2025
A10: PLN | B10: PP15/2025 transfer roster | C10: BKI → DAM (statutory baseline) | D10: Energy OilGas | E10: Electricity generation, grids and distribution | F10: Series B / C transfer baseline, not proof of sole ownership or October 2026 immediate parent; verify registry | G10: https://peraturan.bpk.go.id/Details/316689/pp-no-15-tahun-2025
A11: MIND ID | B11: PP15/2025 transfer roster | C11: BKI → DAM (statutory baseline) | D11: CoalandMinerals | E11: Mining and mineral holding | F11: Series B / C transfer baseline, not proof of sole ownership or October 2026 immediate parent; verify registry | G11: https://peraturan.bpk.go.id/Details/316689/pp-no-15-tahun-2025
A12: Bank Rakyat Indonesia (BRI) | B12: PP15/2025 transfer roster | C12: BKI → DAM (statutory baseline) | D12: FinancialServices | E12: Banking | F12: Series B / C transfer baseline, not proof of sole ownership or October 2026 immediate parent; verify registry | G12: https://peraturan.bpk.go.id/Details/316689/pp-no-15-tahun-2025
A13: Bank Negara Indonesia (BNI) | B13: PP15/2025 transfer roster | C13: BKI → DAM (statutory baseline) | D13: FinancialServices | E13: Banking | F13: Series B / C transfer baseline, not proof of sole ownership or October 2026 immediate parent; verify registry | G13: https://peraturan.bpk.go.id/Details/316689/pp-no-15-tahun-2025
A14: Bank Mandiri | B14: PP15/2025 transfer roster | C14: BKI → DAM (statutory baseline) | D14: FinancialServices | E14: Banking | F14: Series B / C transfer baseline, not proof of sole ownership or October 2026 immediate parent; verify registry | G14: https://peraturan.bpk.go.id/Details/316689/pp-no-15-tahun-2025
A15: Bank Tabungan Negara (BTN) | B15: PP15/2025 transfer roster | C15: BKI → DAM (statutory baseline) | D15: FinancialServices | E15: Housing / retail banking | F15: Series B / C transfer baseline, not proof of sole ownership or October 2026 immediate parent; verify registry | G15: https://peraturan.bpk.go.id/Details/316689/pp-no-15-tahun-2025
A16: Telkom Indonesia | B16: PP15/2025 transfer roster | C16: BKI → DAM (statutory baseline) | D16: TelecommunicationMedia | E16: Telecommunications | F16: Series B / C transfer baseline, not proof of sole ownership or October 2026 immediate parent; verify registry | G16: https://peraturan.bpk.go.id/Details/316689/pp-no-15-tahun-2025
... A74: PT Dahana | B74: Selected operating subsidiary | C74: Len Industri / DEFEND ID | D74: Energetic materials | E74: Project delivery / manufacturing candidate | F74: Operating-group mapping; percentages not assessed | G74: https://dahana.id/president-launches-defend-ids-logo-and-name/

Sheet Partners
A1: DANANTARA | Potential global industrial partners
A2: Analyst shortlist, not procurement advice or confirmed project appointment. Select operator versus OEM versus licensor according to project scope; no single partner assumed for unresolved umbrella projects.
A5: Project ID | B5: Project | C5: Potential partner | D5: Partner role | E5: Capability / relationship source | F5: Relationship status | G5: Required diligence | H5: Key execution risk
A6: SP-01 | B6: Silica | C6: Sibelco | D6: Mineral operating partner | E6: https://www.sibelco.com/en/materials/silica | F6: Capability shortlist only; no Danantara award verified | G6: Confirm operating scope, equity appetite, IP/localization, commercial terms, financing and compliance | H6: Ore variability; unclear silica versus silicon scope
A7: SP-02 | B7: Copper | C7: Aurubis | D7: Copper operating / industrial partner | E7: https://www.aurubis.com/en/products/ | F7: Capability shortlist only; no Danantara award verified | G7: Confirm operating scope, equity appetite, IP/localization, commercial terms, financing and compliance | H7: Scope and capacity absent; concentrate balance; product demand
A8: SP-03 | B8: Project Atoma (LTi) | C8: Not shortlisted pending scope | D8: Unresolved | E8: Scope clarification required | F8: Capability shortlist only; no Danantara award verified | G8: Confirm operating scope, equity appetite, IP/localization, commercial terms, financing and compliance | H8: Acronym, resource and economics unconfirmed
A9: SP-04 | B9: Project Tarsius Phase 1 (LTJ) | C9: Lynas Rare Earths | D9: Rare-earth operating partner | E9: https://lynasrareearths.com/kuantan-malaysia-2/ | F9: Capability shortlist only; no Danantara award verified | G9: Confirm operating scope, equity appetite, IP/localization, commercial terms, financing and compliance | H9: Recovery economics; residue management; customer qualification
A10: SP-05 | B10: Al, Fe, Ni, Mn (Auto, Aerospace, Defense) | C10: Rio Tinto (aluminium); POSCO (steel) — package-specific | D10: Industrial operating candidates; no single umbrella operator | E10: https://www.riotinto.com/en/products/aluminium | https://posco.com/homepage/docs/eng7/jsp/company/family/foreign_02_02.jsp | F10: Capability shortlist only; no Danantara award verified | G10: Confirm operating scope, equity appetite, IP/localization, commercial terms, financing and compliance | H10: Umbrella allocation unknown; power intensity; certification
A11: SP-06 | B11: PLTS 100 GW | C11: Masdar | D11: Developer / asset operating partner | E11: https://masdar.ae/en/renewables/our-projects/cirata-floating-photovoltaic-fpv-plant | F11: Masdar–PLN Cirata precedent; not an award for 100 GW program | G11: Confirm operating scope, equity appetite, IP/localization, commercial terms, financing and compliance | H11: Grid hosting capacity; tariff; local content; budget scope
A12: SP-07 | B12: Refinery | C12: Aramco — configuration / commercial fit to be tested | D12: Refinery operating / equity partner candidate; licensors selected separately | E12: https://www.aramco.com/en/what-we-do/energy-products/refined-products | F12: Capability shortlist only; no Danantara award verified | G12: Confirm operating scope, equity appetite, IP/localization, commercial terms, financing and compliance | H12: Crude slate; margin exposure; scope / location absent
A13: SP-08 | B13: Decentralized Waste Management | C13: Veolia | D13: Waste operating partner | E13: https://www.veolia.com/en/solutions/producing-and-recovering-energy-solid-recovered-fuels | F13: Capability shortlist only; no Danantara award verified | G13: Confirm operating scope, equity appetite, IP/localization, commercial terms, financing and compliance | H13: Municipal payment; feedstock quality; collection coverage
A14: SP-09 | B14: Legacy Waste Processing – Landfill Mining | C14: Veolia — conditional remediation scope | D14: Waste operator; site-specific capability review | E14: https://www.veolia.com/en/solutions/producing-and-recovering-energy-solid-recovered-fuels | F14: Capability shortlist only; no Danantara award verified | G14: Confirm operating scope, equity appetite, IP/localization, commercial terms, financing and compliance | H14: Geotechnical / contamination uncertainty; recovered material market
A15: SP-10 | B15: Legacy Waste Processing – RDF | C15: Veolia | D15: RDF operating partner | E15: https://www.veolia.com/en/our-media/press-releases/solvay-and-veolia-launch-energy-transition-project-dombasle-energie | F15: Capability shortlist only; no Danantara award verified | G15: Confirm operating scope, equity appetite, IP/localization, commercial terms, financing and compliance | H15: Calorific / chlorine variability; logistics; offtake
A16: SP-20 | B16: Alutsista | C16: Thales | D16: Systems prime / technology and industrial partner | E16: https://www.danantaraindonesia.co.id/media-center/press-releases/thales-danantara-strategic-technology | F16: Danantara–Thales MoU announced; not a project award | G16: Confirm operating scope, equity appetite, IP/localization, commercial terms, financing and compliance | H16: Procurement visibility; sovereign IP; export controls; sustainment
... A23: SP-27 | B23: Biosimilar & Pharma Manufacturing | C23: Samsung Biologics | D23: Biopharma manufacturing / CDMO partner | E23: https://samsungbiologics.com/ | F23: Capability shortlist only; no Danantara award verified | G23: Confirm operating scope, equity appetite, IP/localization, commercial terms, financing and compliance | H23: IP / freedom to operate; clinical comparability; BPOM approval; quality

Sheet Milestones
A1: DANANTARA | Industrial stage-gate framework
A2: Proposed framework based on CII front-end planning, AACE estimate maturity and technology-readiness practice. These are required future gates, not verified current achievements. Horizons are indicative; approve project-specific dates after scope and FEED.
A5: Gate | B5: Industrial milestone | C5: Required deliverables | D5: Accountable process owner | E5: Acceptance / release criteria | F5: Indicative horizon | G5: Method / source
A6: M0 | B6: Mandate / charter | C6: Approved product scope, site candidates, sponsor, SPV and decision rights | D6: Strategic office + sponsor | E6: Scope completeness; named accountable entity | F6: 1–3 years | G6: Analyst governance framework
A7: M1 | B7: FEL 1 / concept selection | C7: Demand / supply, resource data, alternative routes, preliminary economics | D7: Operator + strategic office | E7: Options screened; downside case; risk register | F7: 1–3 years | G7: https://www.construction-institute.org/pdri-overview
A8: M2 | B8: FEL 2 / pre-feasibility | C8: Pilot results / TRL; site, utilities, feedstock, offtake and environmental baseline | D8: Operator + independent technical adviser | E8: Technology fit; supply / demand evidence; localization plan | F8: 1–3 years | G8: https://www.construction-institute.org/pdri-overview
A9: M3 | B9: FEL 3 / FEED and bankability | C9: FEED, permits, ESIA, cost estimate, EPC strategy and lender diligence | D9: Operator + DIM financing team | E9: Independent readiness review; estimate basis; contingency; safety review | F9: 1–3 years | G9: https://www.construction-institute.org/pdri-overview | https://library.aacei.org/pgd01/pgd01.shtml
A10: M4 | B10: FID / financial close | C10: Board approval; committed financing; bankable contracts; insurance and guarantees | D10: Company board / investment committee | E10: No open critical permits; finance and execution conditions satisfied | F10: 1–3 or 4–7 years | G10: Analyst financing gate; project-specific conditions
A11: M5 | B11: EPC / industrialization | C11: Detailed design, long-lead procurement, supplier quality and local capability | D11: Operator / EPC; DAM monitors portfolio | E11: Schedule / cost control; supplier readiness; change management | F11: 1–3 or 4–7 years | G11: Analyst execution gate
A12: M6 | B12: Mechanical completion / system readiness | C12: Completion dossiers, inspections, safety checks and trained operations team | D12: Operator / EPC / independent certifier | E12: Accepted completion; punch-list risk; operating procedures | F12: 4–7 years typical greenfield | G12: Analyst commissioning gate
A13: M7 | B13: Commissioning / performance acceptance | C13: Performance tests, reliability, environmental compliance and product acceptance | D13: Operator + independent certifier | E13: Contract guarantees met; no unresolved safety-critical defects | F13: 1–3 or 4–7 years | G13: Analyst acceptance gate
A14: M8 | B14: Commercial / regulatory release | C14: COD / customer qualification, class certification or BPOM approval as relevant | D14: Operator + customer / regulator | E14: Saleable product; permits; service readiness; warranty handover | F14: 4–7 years typical greenfield | G14: Analyst industry-specific acceptance
A15: M9 | B15: Ramp-up / benefits realization | C15: Stable output, cost, quality, local suppliers, technology transfer and workforce capability | D15: Operator; DAM benefit monitoring | E15: Actual benefits versus business case; 12-month review; corrective plan | F15: 4–7 years; >8 years ecosystem | G15: Analyst benefits gate
A18: Technology / budget rule: assess TRL independently; do not assume source budgets qualify for an AACE class. Re-estimate at each gate and link contingency to quantified risks.
A20: NASA TRL reference: https://www.nasa.gov/directorates/somd/space-communications-navigation-program/technology-readiness-levels/ | Defense / aerospace use design reviews and qualification; pharma uses GMP validation and regulatory release. These supplement FEL, not replace it.
